Workbook
Name AXPMKT: #REF!
Name backuptotal: #REF!
Name BACMKT: #REF!
Name DGMKT: #REF!
Name DIAMKT: #REF!
Name FTNTMKT: #REF!
Name GOOGLMKT: #REF!
Name GSMKT: #REF!
Name KVUEMKT: #REF!
Name LTCMKT: #REF!
Name OMKT: #REF!
Name PAYCMKT: #REF!
Name PMKTVALUE: #REF!
Name QCOMMKT: #REF!
Name totalexp: #REF!
Name VOOMKT: #REF!
Name VZMKT: #REF!
Name WBAMKT: #REF!

Sheet Raw Data, Screening
A1: Company | B1: Revenue (CAGR) | C1: EBITDA Margin | D1: ROE | E1: ROIC | F1: Debt-to-EBITDA | G1: EPS σ | H1: EV-to-EBITDA | I1: Industry | U1: Screening Score | V1: Column1 | W1: 2025
A2: Chevron | B2: =[1]Notes!$D$7 -> 0.037067093 | C2: =[1]Notes!$D$8 -> 0.21738233 | D2: =[1]Notes!$D$9 -> 0.063998626 | E2: =[1]Notes!$D$10 -> 0.067607237 | F2: =[1]Notes!$D$11 -> 0.9918719 | G2: =[1]Notes!$D$12 -> 6.8587428 | H2: =[1]Notes!$D$13 -> 7.158389 | I2: =[1]Notes!$D$14 -> Oil & Gas Integrated | U2: Revenue (CAGR) | W2: =(([1]Statements!AB21/[1]Statements!V21)^(1/7))-1 -> -1
A3: Bank of America | B3: =[2]Notes!$D$7 -> 0.031147913 | C3: =[2]Notes!$D$8 -> 0.34997392 | D3: =[2]Notes!$D$9 -> 0.095814248 | E3: =[2]Notes!$D$10 -> 0.011570559 | F3: =[2]Notes!$D$11 -> 9.7069638 | G3: =[2]Notes!$D$12 -> 0.62268042 | H3: =[2]Notes!$D$13 -> 5.7999968 | I3: =[2]Notes!$D$14 -> Banks, Diversified | U3: EBITDA Margin | W3: =[1]Statements!AB44/[1]Statements!AB21 -> #DIV/0!
A4: AMD | B4: =[3]Notes!$D$7 -> 0.2636908 | C4: =[3]Notes!$D$8 -> 0.14194983 | D4: =[3]Notes!$D$9 -> 0.06776298 | E4: =[3]Notes!$D$10 -> 0.017265524 | F4: =[3]Notes!$D$11 -> 0.65527761 | G4: =[3]Notes!$D$12 -> 0.9787008 | H4: =[3]Notes!$D$13 -> 77.274818 | I4: =[3]Notes!$D$14 -> Semiconductors | U4: ROE | W4: =[1]Statements!AB38/[1]Statements!AN39 -> #DIV/0!
A5: Amazon | B5: =[4]Notes!$D$6 -> 0.14344471 | C5: =[4]Notes!$D$7 -> 0.11155297 | D5: =[4]Notes!$D$8 -> 0.18894822 | E5: =[4]Notes!$D$9 -> 0.041244089 | F5: =[4]Notes!$D$10 -> 0.82085652 | G5: =[4]Notes!$D$11 -> 2.5375167 | H5: =[4]Notes!$D$12 -> 31.678901 | I5: =[4]Notes!$D$13 -> Internet Retail | U5: ROIC | W5: =([1]Statements!AB34+[1]Statements!AB30)*(1-([1]Statements!AB35/[1]Statements!AB34))/([1]Statements!AN14-[1]Statements!AN32+[1]Statements!AN19) -> #DIV/0!
A6: Applied Materials | B6: =[5]!Table810[[#This Row],[2025]] -> 0.099453462 | C6: =[5]Notes!$D$7 -> 0.29219543 | D6: =[5]Notes!$D$8 -> 0.34278717 | E6: =[5]Notes!$D$9 -> 0.095864899 | F6: =[5]Notes!$D$10 -> 0.79080709 | G6: =[5]Notes!$D$11 -> 2.3251312 | H6: =[5]Notes!$D$12 -> 31.09786 | I6: =[5]Notes!$D$13 -> Semiconductor Equipment & Materials | U6: Debt-to-EBITDA | W6: =[1]Statements!AN43/[1]Statements!AB44 -> #DIV/0!
A7: Cadence Design Systems | B7: =[6]!Table810[[#This Row],[2025]] -> 0.12404466 | C7: =[6]Notes!$D$8 -> 0.28922953 | D7: =[6]Notes!$D$9 -> 0.202567 | E7: =[6]Notes!$D$10 -> 0.064283198 | F7: =[6]Notes!$D$11 -> 1.6189064 | G7: =[6]Notes!$D$12 -> 0.74157179 | H7: =[6]Notes!$D$13 -> 53.937194 | I7: =[6]Notes!$D$14 -> Software | U7: EPS σ | W7: =_xlfn.STDEV.S([1]Statements!V41:AB41) -> 0.29812234
A8: Costco | B8: =[7]Observations!$D$7 -> 0.087804548 | C8: =[7]!Table810[[#This Row],[2025]] -> 0.037724127 | D8: =[7]Observations!$D$9 -> 0.27770539 | E8: =[7]Observations!$D$10 -> 0.23427061 | F8: =[7]Observations!$D$11 -> 0.55022633 | G8: =[7]Observations!$D$12 -> 3.6535036 | H8: =[7]Observations!$D$13 -> 39.487034 | I8: =[7]Observations!$D$14 -> Discount Stores | U8: EV-to-EBITDA | W8: =[1]Statements!AN44/[1]Statements!AB44 -> #DIV/0!
A9: Dexcom | B9: =[8]Notes!$D$5 -> 0.17856932 | C9: =[8]Notes!$D$6 -> 0.1955813 | D9: =[8]Notes!$D$7 -> 0.30455208 | E9: =[8]Notes!$D$8 -> 0.20161871 | F9: =[8]!Table810[[#This Row],[2025]] -> 1.3609344 | G9: =[8]Notes!$D$10 -> 0.61154704 | H9: =[8]Notes!$D$11 -> 31.65159 | I9: =[8]Notes!$D$12 -> Medical Devices | U9: Industry | W9: Oil & Gas Integrated
A10: Elevance Health | B10: =[9]Notes!$D$5 -> 0.096912497 | C10: =[9]Notes!$D$6 -> 0.043892028 | D10: =[9]Notes!$D$7 -> 0.12858311 | E10: =[9]Notes!$D$8 -> 0.1383875 | F10: =[9]Notes!$D$9 -> 3.6665904 | G10: =[9]!Table810[[#This Row],[2025]] -> 3.3412957 | H10: =[9]Notes!$D$11 -> 11.41099 | I10: =[9]Notes!$D$12 -> Healthcare
A11: Fortinet | B11: {=TRANSPOSE([10]!Table810[2025])} -> 0.17777133 | C11: 0.30659156 | D11: 1.497697 | E11: 0.61386983 | F11: 0.47791049 | G11: 0.77956319 | H11: 28.562957 | I11: Software
A12: Delta Airlines | B12: {=TRANSPOSE([11]!Table810[2025])} -> 0.043579938 | C12: 0.091881826 | D12: 0.24001343 | E12: 0.12021862 | F12: 2.4239093 | G12: 9.6578962 | H12: 8.3207077 | I12: Airlines
A13: FedEx | B13: {=TRANSPOSE([12]!Table810[2025])} -> 0.03375663 | C13: 0.059333985 | D13: 0.14575245 | E13: 0.073614115 | F13: 3.9446042 | G13: 6.6980748 | H13: 13.006358 | I13: Freight & Logistics
A14: Starbucks | B14: {=TRANSPOSE([13]!Table810[2025])} -> 0.049536841 | C14: 0.12428061 | D14: -0.22951975 | E14: 0.22890089 | F14: 3.4784152 | G14: 1.0618675 | H14: 34.833562 | I14: Restaurants
A15: Kratos Defense | B15: {=TRANSPOSE([14]!Table810[2025])} -> 0.094129539 | C15: 0.019008019 | D15: 0.011020388 | E15: 0.0095220492 | F15: 0 | G15: 0.28429854 | H15: 642.83797 | I15: Aerospace & Defense
A16: California Water Service Group | B16: {=TRANSPOSE([15]!Table810[2025])} -> 0.049203495 | C16: 0.37018362 | D16: 0.075572317 | E16: 0.028084799 | F16: 4.3330731 | G16: 0.79501835 | H16: 11.160364 | I16: Utilities
A17: Broadcom | B17: {=TRANSPOSE([16]!Table810[2025])} -> 0.16005944 | C17: 0.4306823 | D17: 0.28448064 | E17: 0.22867202 | F17: 2.3672906 | G17: 9.0838295 | H17: 72.568037 | I17: Semiconductors
A18: Exxon Mobil | B18: {=TRANSPOSE([17]!Table810[2025])} -> 0.032827288 | C18: 0.27982887 | D18: 0.1078627 | E18: 0.1554335 | F18: 0.3683967 | G18: 5.7462639 | H18: 6.7156586 | I18: Oil & Gas Integrated

Sheet Dashboard, Screening
B3: Row Labels | C3: Revenue (CAGR) μ | D3: EBITDA Margin μ | E3: ROEμ | F3: ROICμ | G3: D/Eμ | H3: EPS σ μ | I3: EV-to-EBITDAμ
B4: Aerospace & Defense | C4: 0.094129539 | D4: 0.019008019 | E4: 0.011020388 | F4: 0.0095220492 | G4: 0 | H4: 0.28429854 | I4: 642.83797
B5: Kratos Defense | C5: 0.094129539 | D5: 0.019008019 | E5: 0.011020388 | F5: 0.0095220492 | G5: 0 | H5: 0.28429854 | I5: 642.83797
B6: Airlines | C6: 0.043579938 | D6: 0.091881826 | E6: 0.24001343 | F6: 0.12021862 | G6: 2.4239093 | H6: 9.6578962 | I6: 8.3207077
B7: Delta Airlines | C7: 0.043579938 | D7: 0.091881826 | E7: 0.24001343 | F7: 0.12021862 | G7: 2.4239093 | H7: 9.6578962 | I7: 8.3207077
B8: Banks, Diversified | C8: 0.031147913 | D8: 0.34997392 | E8: 0.095814248 | F8: 0.011570559 | G8: 9.7069638 | H8: 0.62268042 | I8: 5.7999968
B9: Bank of America | C9: 0.031147913 | D9: 0.34997392 | E9: 0.095814248 | F9: 0.011570559 | G9: 9.7069638 | H9: 0.62268042 | I9: 5.7999968
B10: Discount Stores | C10: 0.087804548 | D10: 0.037724127 | E10: 0.27770539 | F10: 0.23427061 | G10: 0.55022633 | H10: 3.6535036 | I10: 39.487034
B11: Costco | C11: 0.087804548 | D11: 0.037724127 | E11: 0.27770539 | F11: 0.23427061 | G11: 0.55022633 | H11: 3.6535036 | I11: 39.487034
B12: Freight & Logistics | C12: 0.03375663 | D12: 0.059333985 | E12: 0.14575245 | F12: 0.073614115 | G12: 3.9446042 | H12: 6.6980748 | I12: 13.006358
B13: FedEx | C13: 0.03375663 | D13: 0.059333985 | E13: 0.14575245 | F13: 0.073614115 | G13: 3.9446042 | H13: 6.6980748 | I13: 13.006358
B14: Healthcare | C14: 0.096912497 | D14: 0.043892028 | E14: 0.12858311 | F14: 0.1383875 | G14: 3.6665904 | H14: 3.3412957 | I14: 11.41099
B15: Elevance Health | C15: 0.096912497 | D15: 0.043892028 | E15: 0.12858311 | F15: 0.1383875 | G15: 3.6665904 | H15: 3.3412957 | I15: 11.41099
... B34: Grand Total | C34: 0.10438576 | D34: 0.19259021 | E34: 0.23110845 | F34: 0.13593717 | G34: 2.3242273 | H34: 3.1269524 | I34: 68.79917

Sheet Optimization
B3: Portfolio Simulator | I3: Data Showcase
B4: Ticker | C4: Name | D4: Shares | E4: Price | F4: Mkt Value | G4: Pos Ratio | J4: R, 2017 | K4: R, 2018 | L4: R, 2019 | M4: R, 2020 | N4: R, 2021 | O4: R. 2022 | P4: R, 2023 | Q4: R, 2024 | R4: R, 2025 | S4: μ | T4: σ | U4: β
B5: VOO | C5: #VALUE! | D5: 6.374 | E5: {=_FV(C5,"Price")} -> 680.95 | F5: =D5*E5 -> 4340.3753 | G5: =F5/$F$27 -> 0.10774474 | I5: VOO | J5: ='Data & Analysis'!AC5 -> 0.25263356 | K5: ='Data & Analysis'!AD5 -> -0.0031294809 | L5: ='Data & Analysis'!AE5 -> 0.21657086 | M5: ='Data & Analysis'!AF5 -> 0.17493662 | N5: ='Data & Analysis'!AG5 -> 0.22327455 | O5: ='Data & Analysis'!AH5 -> -0.069349585 | P5: ='Data & Analysis'!AI5 -> 0.20317025 | Q5: ='Data & Analysis'!AJ5 -> 0.24575445 | R5: ='Data & Analysis'!AK5 -> 0.22730931 | S5: =AVERAGE(J5:R5) -> 0.16346339 | T5: =_xlfn.STDEV.S(J5:R5) -> 0.11665149 | U5: {=_FV('Data & Analysis'!C5,"Beta")} -> 1.0001
B6: BAC | C6: #VALUE! | D6: 76.3492 | E6: {=_FV(C6,"Price")} -> 57.875 | F6: =D6*E6 -> 4418.7099 | G6: =F6/$F$27 -> 0.10968931 | I6: DIA | J6: ='Data & Analysis'!AC6 -> 0.31990622 | K6: ='Data & Analysis'!AD6 -> 9.7742591e-05 | L6: ='Data & Analysis'!AE6 -> 0.16704114 | M6: ='Data & Analysis'!AF6 -> 0.10187341 | N6: ='Data & Analysis'!AG6 -> 0.19203014 | O6: ='Data & Analysis'!AH6 -> 0.009112192 | P6: ='Data & Analysis'!AI6 -> 0.15036946 | Q6: ='Data & Analysis'!AJ6 -> 0.18746589 | R6: ='Data & Analysis'!AK6 -> 0.18390247 | S6: =AVERAGE(J6:R6) -> 0.14575541 | T6: =_xlfn.STDEV.S(J6:R6) -> 0.098711919 | U6: {=_FV('Data & Analysis'!C6,"Beta")} -> 0.9322
B7: COST | C7: #VALUE! | D7: 3 | E7: {=_FV(C7,"Price")} -> 946.68 | F7: =D7*E7 -> 2840.04 | G7: =F7/$F$27 -> 0.070500671 | I7: TSLA | J7: ='Data & Analysis'!AC7 -> 0.34071492 | K7: ='Data & Analysis'!AD7 -> -0.14313341 | L7: ='Data & Analysis'!AE7 -> 0.75080756 | M7: ='Data & Analysis'!AF7 -> 1.8081111 | N7: ='Data & Analysis'!AG7 -> 0.16589307 | O7: ='Data & Analysis'!AH7 -> -0.58920966 | P7: ='Data & Analysis'!AI7 -> 0.078095755 | Q7: ='Data & Analysis'!AJ7 -> 0.77024071 | R7: ='Data & Analysis'!AK7 -> 0.017736 | S7: =AVERAGE(J7:R7) -> 0.35547289 | T7: =_xlfn.STDEV.S(J7:R7) -> 0.68980754 | U7: {=_FV('Data & Analysis'!C7,"Beta")} -> 1.8242 | XEC7: Current Stock Portfolio
B8: AMZN | C8: #VALUE! | D8: 12 | E8: {=_FV(C8,"Price")} -> 240.14 | F8: =D8*E8 -> 2881.68 | G8: =F8/$F$27 -> 0.071534336 | I8: BAC | J8: ='Data & Analysis'!AC8 -> 0.37630852 | K8: ='Data & Analysis'!AD8 -> -0.076390847 | L8: ='Data & Analysis'!AE8 -> 0.18782742 | M8: ='Data & Analysis'!AF8 -> -0.04856196 | N8: ='Data & Analysis'!AG8 -> 0.47975337 | O8: ='Data & Analysis'!AH8 -> -0.21369915 | P8: ='Data & Analysis'!AI8 -> 0.015947382 | Q8: ='Data & Analysis'!AJ8 -> 0.35553863 | R8: ='Data & Analysis'!AK8 -> 0.26063473 | S8: =AVERAGE(J8:R8) -> 0.14859534 | T8: =_xlfn.STDEV.S(J8:R8) -> 0.23895057 | U8: {=_FV('Data & Analysis'!C8,"Beta")} -> 1.1436 | XEC8: Ticker | XED8: Name | XEE8: Shares | XEF8: Price | XEG8: Mkt Value | XEH8: Pos Ratio
B9: O | C9: #VALUE! | D9: 30.81227 | E9: {=_FV(C9,"Price")} -> 63.025 | F9: =D9*E9 -> 1941.9433 | G9: =F9/$F$27 -> 0.048206472 | I9: SBUX | J9: ='Data & Analysis'!AC9 -> 0.068469403 | K9: ='Data & Analysis'!AD9 -> 0.22688187 | L9: ='Data & Analysis'!AE9 -> 0.25734346 | M9: ='Data & Analysis'!AF9 -> 0.17168137 | N9: ='Data & Analysis'!AG9 -> 0.052102103 | O9: ='Data & Analysis'!AH9 -> 0.14725009 | P9: ='Data & Analysis'!AI9 -> -0.11495003 | Q9: ='Data & Analysis'!AJ9 -> 0.19366658 | R9: ='Data & Analysis'!AK9 -> 0.0094611099 | S9: =AVERAGE(J9:R9) -> 0.112434 | T9: =_xlfn.STDEV.S(J9:R9) -> 0.11900523 | U9: {=_FV('Data & Analysis'!C9,"Beta")} -> 0.9479 | XEC9: VOO | XED9: #VALUE! | XEE9: 6.374 | XEF9: {=_FV(XED9,"Price")} -> 680.95 | XEG9: =XEE9*XEF9 -> 4340.3753 | XEH9: =XEG9/$XEG$33 -> 0.10776749
B10: SBUX | C10: #VALUE! | D10: 18.2754 | E10: {=_FV(C10,"Price")} -> 104.06 | F10: =D10*E10 -> 1901.7381 | G10: =F10/$F$27 -> 0.047208425 | I10: O | J10: ='Data & Analysis'!AC10 -> -0.0033746044 | K10: ='Data & Analysis'!AD10 -> 0.35510338 | L10: ='Data & Analysis'!AE10 -> 0.21499874 | M10: ='Data & Analysis'!AF10 -> -0.17896252 | N10: ='Data & Analysis'!AG10 -> 0.2826536 | O10: ='Data & Analysis'!AH10 -> 0.071207577 | P10: ='Data & Analysis'!AI10 -> -0.10759247 | Q10: ='Data & Analysis'!AJ10 -> 0.11423381 | R10: ='Data & Analysis'!AK10 -> 0.24007396 | S10: =AVERAGE(J10:R10) -> 0.10981572 | T10: =_xlfn.STDEV.S(J10:R10) -> 0.18133222 | U10: {=_FV('Data & Analysis'!C10,"Beta")} -> 0.7105 | XEC10: BAC | XED10: #VALUE! | XEE10: 76.3492 | XEF10: {=_FV(XED10,"Price")} -> 57.875 | XEG10: =XEE10*XEF10 -> 4418.7099 | XEH10: =XEG10/$XEG$33 -> 0.10971247
B11: DIA | C11: #VALUE! | D11: 4.787 | E11: {=_FV(C11,"Price")} -> 521.71 | F11: =D11*E11 -> 2497.4258 | G11: =F11/$F$27 -> 0.061995674 | I11: VZ | J11: ='Data & Analysis'!AC11 -> 0.20947157 | K11: ='Data & Analysis'!AD11 -> 0.1260411 | L11: ='Data & Analysis'!AE11 -> 0.17388834 | M11: ='Data & Analysis'!AF11 -> 0.019774755 | N11: ='Data & Analysis'!AG11 -> 0.075536227 | O11: ='Data & Analysis'!AH11 -> -0.12091901 | P11: ='Data & Analysis'!AI11 -> 0.15773565 | Q11: ='Data & Analysis'!AJ11 -> 0.06191901 | R11: ='Data & Analysis'!AK11 -> 0.23916904 | S11: =AVERAGE(J11:R11) -> 0.10473519 | T11: =_xlfn.STDEV.S(J11:R11) -> 0.11062957 | U11: {=_FV('Data & Analysis'!C11,"Beta")} -> 0.2253 | XEC11: COST | XED11: #VALUE! | XEE11: 3 | XEF11: {=_FV(XED11,"Price")} -> 946.68 | XEG11: =XEE11*XEF11 -> 2840.04 | XEH11: =XEG11/$XEG$33 -> 0.070515558
B12: VZ | C12: #VALUE! | D12: 50.42404 | E12: {=_FV(C12,"Price")} -> 44.08 | F12: =D12*E12 -> 2222.6917 | G12: =F12/$F$27 -> 0.055175721 | I12: AMZN | J12: ='Data & Analysis'!AC12 -> 0.5664283 | K12: ='Data & Analysis'!AD12 -> 0.16951124 | L12: ='Data & Analysis'!AE12 -> 0.15591116 | M12: ='Data & Analysis'!AF12 -> 0.46754891 | N12: ='Data & Analysis'!AG12 -> -0.06934493 | O12: ='Data & Analysis'!AH12 -> -0.37177418 | P12: ='Data & Analysis'!AI12 -> 0.40872428 | Q12: ='Data & Analysis'!AJ12 -> 0.42621062 | R12: ='Data & Analysis'!AK12 -> 0.010296855 | S12: =AVERAGE(J12:R12) -> 0.19594581 | T12: =_xlfn.STDEV.S(J12:R12) -> 0.30388615 | U12: {=_FV('Data & Analysis'!C12,"Beta")} -> 1.4742 | XEC12: V | XED12: #VALUE! | XEE12: 8 | XEF12: {=_FV(XED12,"Price")} -> 341.59 | XEG12: =XEE12*XEF12 -> 2732.72 | XEH12: =XEG12/$XEG$33 -> 0.067850902
B13: V | C13: #VALUE! | D13: 8 | E13: {=_FV(C13,"Price")} -> 341.59 | F13: =D13*E13 -> 2732.72 | G13: =F13/$F$27 -> 0.067836578 | I13: GOOGL | J13: ='Data & Analysis'!AC13 -> 0.36564515 | K13: ='Data & Analysis'!AD13 -> -0.048866815 | L13: ='Data & Analysis'!AE13 -> 0.24104707 | M13: ='Data & Analysis'!AF13 -> 0.24320795 | N13: ='Data & Analysis'!AG13 -> 0.39267333 | O13: ='Data & Analysis'!AH13 -> -0.31407281 | P13: ='Data & Analysis'!AI13 -> 0.34888182 | Q13: ='Data & Analysis'!AJ13 -> 0.38244328 | R13: ='Data & Analysis'!AK13 -> 0.55502507 | S13: =AVERAGE(J13:R13) -> 0.24066489 | T13: =_xlfn.STDEV.S(J13:R13) -> 0.26479476 | U13: {=_FV('Data & Analysis'!C13,"Beta")} -> 1.2646 | XEC13: AMZN | XED13: #VALUE! | XEE13: 12 | XEF13: {=_FV(XED13,"Price")} -> 240.14 | XEG13: =XEE13*XEF13 -> 2881.68 | XEH13: =XEG13/$XEG$33 -> 0.071549441
B14: TSLA | C14: #VALUE! | D14: 2 | E14: {=_FV(C14,"Price")} -> 411.84 | F14: =D14*E14 -> 823.68 | G14: =F14/$F$27 -> 0.020446893 | I14: CRM | J14: ='Data & Analysis'!AC14 -> 0.36461473 | K14: ='Data & Analysis'!AD14 -> 0.28832505 | L14: ='Data & Analysis'!AE14 -> 0.18200012 | M14: ='Data & Analysis'!AF14 -> 0.21288099 | N14: ='Data & Analysis'!AG14 -> 0.030878903 | O14: ='Data & Analysis'!AH14 -> -0.32567972 | P14: ='Data & Analysis'!AI14 -> 0.51488428 | Q14: ='Data & Analysis'!AJ14 -> 0.20553179 | R14: ='Data & Analysis'!AK14 -> -0.75655115 | S14: =AVERAGE(J14:R14) -> 0.079653887 | T14: =_xlfn.STDEV.S(J14:R14) -> 0.39117683 | U14: {=_FV('Data & Analysis'!C14,"Beta")} -> 1.1916 | XEC14: O | XED14: #VALUE! | XEE14: 43.81227 | XEF14: {=_FV(XED14,"Price")} -> 63.025 | XEG14: =XEE14*XEF14 -> 2761.2683 | XEH14: =XEG14/$XEG$33 -> 0.06855973
B15: CRM | C15: #VALUE! | D15: 6 | E15: {=_FV(C15,"Price")} -> 157.97 | F15: =D15*E15 -> 947.82 | G15: =F15/$F$27 -> 0.023528523 | I15: CVX | J15: ='Data & Analysis'!AC15 -> 0.20442238 | K15: ='Data & Analysis'!AD15 -> -0.00011143924 | L15: ='Data & Analysis'!AE15 -> 0.027877579 | M15: ='Data & Analysis'!AF15 -> -0.10254983 | N15: ='Data & Analysis'!AG15 -> 0.52968203 | O15: ='Data & Analysis'!AH15 -> 0.35283573 | P15: ='Data & Analysis'!AI15 -> -0.084009611 | Q15: ='Data & Analysis'!AJ15 -> 0.098241008 | R15: ='Data & Analysis'!AK15 -> 0.19563423 | S15: =AVERAGE(J15:R15) -> 0.13578023 | T15: =_xlfn.STDEV.S(J15:R15) -> 0.20832471 | U15: {=_FV('Data & Analysis'!C15,"Beta")} -> 0.4901 | XEC15: DIA | XED15: #VALUE! | XEE15: 4.787 | XEF15: {=_FV(XED15,"Price")} -> 521.71 | XEG15: =XEE15*XEF15 -> 2497.4258 | XEH15: =XEG15/$XEG$33 -> 0.062008765
B16: CVX | C16: #VALUE! | D16: 9.22635 | E16: {=_FV(C16,"Price")} -> 168.43 | F16: =D16*E16 -> 1553.9941 | G16: =F16/$F$27 -> 0.038576087 | I16: AMD | J16: ='Data & Analysis'!AC16 -> 0.28139426 | K16: ='Data & Analysis'!AD16 -> 0.5746816 | L16: ='Data & Analysis'!AE16 -> 0.65515472 | M16: ='Data & Analysis'!AF16 -> 0.60000486 | N16: ='Data & Analysis'!AG16 -> 0.28823657 | O16: ='Data & Analysis'!AH16 -> -0.41890291 | P16: ='Data & Analysis'!AI16 -> 0.80263092 | Q16: ='Data & Analysis'!AJ16 -> -0.36895797 | R16: ='Data & Analysis'!AK16 -> 1.5374652 | S16: =AVERAGE(J16:R16) -> 0.43907858 | T16: =_xlfn.STDEV.S(J16:R16) -> 0.59856816 | U16: {=_FV('Data & Analysis'!C16,"Beta")} -> 2.4703 | XEC16: VZ | XED16: #VALUE! | XEE16: 50.42404 | XEF16: {=_FV(XED16,"Price")} -> 44.08 | XEG16: =XEE16*XEF16 -> 2222.6917 | XEH16: =XEG16/$XEG$33 -> 0.055187372
B17: AMD | C17: #VALUE! | D17: 5 | E17: {=_FV(C17,"Price")} -> 539.49 | F17: =D17*E17 -> 2697.45 | G17: =F17/$F$27 -> 0.066961041 | I17: LULU | J17: ='Data & Analysis'!AC17 -> 0.14712178 | K17: ='Data & Analysis'!AD17 -> 0.63653015 | L17: ='Data & Analysis'!AE17 -> 0.48216636 | M17: ='Data & Analysis'!AF17 -> 0.31699061 | N17: ='Data & Analysis'!AG17 -> 0.015337539 | O17: ='Data & Analysis'!AH17 -> -0.08396538 | P17: ='Data & Analysis'!AI17 -> 0.39124385 | Q17: ='Data & Analysis'!AJ17 -> -0.091351695 | R17: ='Data & Analysis'!AK17 -> -1.2876099 | S17: =AVERAGE(J17:R17) -> 0.058495927 | T17: =_xlfn.STDEV.S(J17:R17) -> 0.56520222 | U17: {=_FV('Data & Analysis'!C17,"Beta")} -> 0.8798 | XEC17: SBUX | XED17: #VALUE! | XEE17: 18.2754 | XEF17: {=_FV(XED17,"Price")} -> 104.06 | XEG17: =XEE17*XEF17 -> 1901.7381 | XEH17: =XEG17/$XEG$33 -> 0.047218393
B18: LULU | C18: #VALUE! | D18: 7 | E18: {=_FV(C18,"Price")} -> 114.29 | F18: =D18*E18 -> 800.03 | G18: =F18/$F$27 -> 0.019859809 | I18: LMT | J18: ='Data & Analysis'!AC18 -> 0.39590723 | K18: ='Data & Analysis'!AD18 -> -0.14416424 | L18: ='Data & Analysis'!AE18 -> 0.4403192 | M18: ='Data & Analysis'!AF18 -> -0.22595726 | N18: ='Data & Analysis'!AG18 -> 0.24940204 | O18: ='Data & Analysis'!AH18 -> 0.22644398 | P18: ='Data & Analysis'!AI18 -> -0.019885852 | Q18: ='Data & Analysis'!AJ18 -> 0.12880175 | R18: ='Data & Analysis'!AK18 -> 0.12960543 | S18: =AVERAGE(J18:R18) -> 0.13116359 | T18: =_xlfn.STDEV.S(J18:R18) -> 0.22773058 | U18: {=_FV('Data & Analysis'!C18,"Beta")} -> 0.1212 | XEC18: CRM | XED18: #VALUE! | XEE18: 6 | XEF18: {=_FV(XED18,"Price")} -> 157.97 | XEG18: =XEE18*XEF18 -> 947.82 | XEH18: =XEG18/$XEG$33 -> 0.023533491
B19: GOOGL | C19: #VALUE! | D19: 4.57222 | E19: {=_FV(C19,"Price")} -> 353.65 | F19: =D19*E19 -> 1616.9656 | G19: =F19/$F$27 -> 0.04013928 | I19: UPS | J19: ='Data & Analysis'!AC19 -> 0.21877248 | K19: ='Data & Analysis'!AD19 -> -0.11318196 | L19: ='Data & Analysis'!AE19 -> 0.060653471 | M19: ='Data & Analysis'!AF19 -> 0.46855365 | N19: ='Data & Analysis'!AG19 -> 0.31079914 | O19: ='Data & Analysis'!AH19 -> -0.018299312 | P19: ='Data & Analysis'!AI19 -> -0.17837337 | Q19: ='Data & Analysis'!AJ19 -> -0.1116137 | R19: ='Data & Analysis'!AK19 -> 0.056620972 | S19: =AVERAGE(J19:R19) -> 0.077103487 | T19: =_xlfn.STDEV.S(J19:R19) -> 0.2164486 | U19: {=_FV('Data & Analysis'!C19,"Beta")} -> 1.0164 | XEC19: CVX | XED19: #VALUE! | XEE19: 9.22635 | XEF19: {=_FV(XED19,"Price")} -> 168.43 | XEG19: =XEE19*XEF19 -> 1553.9941 | XEH19: =XEG19/$XEG$33 -> 0.038584232
B20: LMT | C20: #VALUE! | D20: 2.0881 | E20: {=_FV(C20,"Price")} -> 502.09 | F20: =D20*E20 -> 1048.4141 | G20: =F20/$F$27 -> 0.026025655 | I20: XOM | J20: ='Data & Analysis'!AC20 -> 0.12596392 | K20: ='Data & Analysis'!AD20 -> -0.075658468 | L20: ='Data & Analysis'!AE20 -> -0.048546703 | M20: ='Data & Analysis'!AF20 -> -0.1591883 | N20: ='Data & Analysis'!AG20 -> 0.63795981 | O20: ='Data & Analysis'!AH20 -> 0.49536374 | P20: ='Data & Analysis'!AI20 -> -0.049823384 | Q20: ='Data & Analysis'!AJ20 -> 0.10815792 | R20: ='Data & Analysis'!AK20 -> 0.29773109 | S20: =AVERAGE(J20:R20) -> 0.14799551 | T20: =_xlfn.STDEV.S(J20:R20) -> 0.27553743 | U20: {=_FV('Data & Analysis'!C20,"Beta")} -> 0.1723 | XEC20: XOM | XED20: #VALUE! | XEE20: 10.9633 | XEF20: {=_FV(XED20,"Price")} -> 136.04 | XEG20: =XEE20*XEF20 -> 1491.4473 | XEH20: =XEG20/$XEG$33 -> 0.037031253
... B24: SO | C24: #VALUE! | D24: 11.0205 | E24: {=_FV(C24,"Price")} -> 96.75 | F24: =D24*E24 -> 1066.2334 | G24: =F24/$F$27 -> 0.026467996 | I24: DUK | J24: ='Data & Analysis'!AC24 -> 0.10045711 | K24: ='Data & Analysis'!AD24 -> 0.21050135 | L24: ='Data & Analysis'!AE24 -> 0.19606773 | M24: ='Data & Analysis'!AF24 -> 0.052736296 | N24: ='Data & Analysis'!AG24 -> 0.19234302 | O24: ='Data & Analysis'!AH24 -> 0.055722029 | P24: ='Data & Analysis'!AI24 -> 0.020597051 | Q24: ='Data & Analysis'!AJ24 -> 0.23311266 | R24: ='Data & Analysis'!AK24 -> 0.19547871 | S24: =AVERAGE(J24:R24) -> 0.13966844 | T24: =_xlfn.STDEV.S(J24:R24) -> 0.081500862 | U24: {=_FV('Data & Analysis'!C24,"Beta")} -> 0.361 | XEC24: GOOGL | XED24: #VALUE! | XEE24: 4.57222 | XEF24: {=_FV(XED24,"Price")} -> 353.65 | XEG24: =XEE24*XEF24 -> 1616.9656 | XEH24: =XEG24/$XEG$33 -> 0.040147756
B25: n/a | C25: n/a | D25: n/a | E25: n/a | F25: n/a | G25: 0 | XEC25: LMT | XED25: #VALUE! | XEE25: 2.0881 | XEF25: {=_FV(XED25,"Price")} -> 502.09 | XEG25: =XEE25*XEF25 -> 1048.4141 | XEH25: =XEG25/$XEG$33 -> 0.02603115
B26: n/a | C26: n/a | D26: n/a | E26: n/a | F26: n/a | G26: 0 | XEC26: SO | XED26: #VALUE! | XEE26: 9.2205 | XEF26: {=_FV(XED26,"Price")} -> 96.75 | XEG26: =XEE26*XEF26 -> 892.08337 | XEH26: =XEG26/$XEG$33 -> 0.022149602
E27: Total | F27: =SUM(F5:F24) -> 40283.872 | G27: =SUM(G5:G24) -> 1 | XEC27: UPS | XED27: #VALUE! | XEE27: 8.13097 | XEF27: {=_FV(XED27,"Price")} -> 107.98 | XEG27: =XEE27*XEF27 -> 877.98214 | XEH27: =XEG27/$XEG$33 -> 0.021799482
E28: Current P | F28: =XEG31 -> 40275.367 | XEC28: DUK | XED28: #VALUE! | XEE28: 4.47715 | XEF28: {=_FV(XED28,"Price")} -> 128.31 | XEG28: =XEE28*XEF28 -> 574.46312 | XEH28: =XEG28/$XEG$33 -> 0.014263386
E29: Deficit/Surp | F29: =F28-F27 -> -8.5044055 | XEC29: n/a | XED29: n/a | XEE29: n/a | XEF29: n/a | XEG29: n/a | XEH29: 0
XEC30: n/a | XED30: n/a | XEE30: n/a | XEF30: n/a | XEG30: n/a | XEH30: 0
B31: Portfolio Consensus | I31: Portfolio Optimization Simulation | XEF31: Total | XEG31: =SUM(XEG9:XEG28) -> 40275.367 | XEH31: =SUM(XEH9:XEH28) -> 1
C32: Sector | E32: Industry | I32: Scenario | J32: Current | K32: Simulation | L32: Equal WT | M32: Max μP | N32: Max μP | O32: Max μP | P32: Max μP | Q32: Min σP | R32: Min σP | S32: Min σP | T32: Max μ/σP | U32: Min σP | XEF32: Cash | XEG32: 0
B33: VOO | C33: Large blend | E33: N/A | I33: Main Constraint | J33: None | K33: None | L33: None | M33: μP <= 16% | N33: σP <= 14% | O33: σP <= 10% | P33: n/a | Q33: n/a | R33: μP <= 20% | S33: μP <= 18% | T33: n/a | U33: μ/σP = 2 | XEF33: Total C Val | XEG33: =XEG31+XEG32 -> 40275.367
B34: BAC | C34: Financial Services | E34: Banks | J34: --------------------------------------------------------------------------------------------------------------Portfolio Weights----------------------------------------------------------------------------------------------------------------------
B35: TSLA | C35: Consumer Cyclical | E35: Auto Manufacturer | I35: VOO | J35: =XEH9 -> 0.10776749 | K35: =G5 -> 0.10774474 | L35: 0.05 | M35: 0.11124072 | N35: 0.015 | O35: 0.015 | P35: 0.065 | Q35: 0.062101471 | R35: 0.015 | S35: 0.033242567 | T35: 0.056337418 | U35: 0.015
B36: O | C36: Real Estate | E36: REIT | I36: BAC | J36: =XEH10 -> 0.10971247 | K36: =G6 -> 0.10968931 | L36: 0.05 | M36: 0.076117907 | N36: 0.015 | O36: 0.015 | P36: 0.065 | Q36: 0.12 | R36: 0.015 | S36: 0.12 | T36: 0.12 | U36: 0.12
B37: VZ | C37: Communication Services | E37: Telecom | I37: TSLA | J37: =XEH21 -> 0.029250343 | K37: =G14 -> 0.020446893 | L37: 0.05 | M37: 0.015 | N37: 0.12 | O37: 0.058251972 | P37: 0.12 | Q37: 0.015 | R37: 0.046767986 | S37: 0.015 | T37: 0.015 | U37: 0.015
B38: AMZN | C38: Consumer Cyclical | E38: Internet | I38: O | J38: =XEH14 -> 0.06855973 | K38: =G9 -> 0.048206472 | L38: 0.05 | M38: 0.03035951 | N38: 0.015 | O38: 0.015 | P38: 0.12 | Q38: 0.015 | R38: 0.015 | S38: 0.015 | T38: 0.015 | U38: 0.015
B39: SBUX | C39: Consumer Cyclical | E39: Restaurants | I39: VZ | J39: =XEH16 -> 0.055187372 | K39: =G12 -> 0.055175721 | L39: 0.05 | M39: 0.034901224 | N39: 0.015 | O39: 0.038503826 | P39: 0.12 | Q39: 0.12 | R39: 0.089076084 | S39: 0.12 | T39: 0.12 | U39: 0.12
B40: DIA | C40: Large blend | E40: N/A | I40: AMZN | J40: =XEH13 -> 0.071549441 | K40: =G8 -> 0.071534336 | L40: 0.05 | M40: 0.035230068 | N40: 0.015 | O40: 0.015 | P40: 0.12 | Q40: 0.035 | R40: 0.015 | S40: 0.04027353 | T40: 0.051669185 | U40: 0.035
B41: GOOGL | C41: Technology | E41: Internet | I41: SBUX | J41: =XEH17 -> 0.047218393 | K41: =G10 -> 0.047208425 | L41: 0.05 | M41: 0.035868162 | N41: 0.015 | O41: 0.015 | P41: -0.13862172 | Q41: 0.12 | R41: 0.015 | S41: 0.015 | T41: 0.015 | U41: 0.12
B42: CRM | C42: Technology | E42: Software | I42: DIA | J42: =XEH15 -> 0.062008765 | K42: =G11 -> 0.061995674 | L42: 0.05 | M42: 0.073759283 | N42: 0.079231866 | O42: 0.015 | P42: 0.12 | Q42: 0.020489902 | R42: 0.015 | S42: 0.060650751 | T42: 0.06664723 | U42: 0.015
B43: CVX | C43: Energy | E43: Oil and Gas | I43: GOOGL | J43: =XEH24 -> 0.040147756 | K43: =G19 -> 0.04013928 | L43: 0.05 | M43: 0.070134178 | N43: 0.05 | O43: 0.040904637 | P43: 0.12 | Q43: 0.015 | R43: 0.0458487 | S43: 0.015 | T43: 0.015 | U43: 0.015
B44: AMD | C44: Technology | E44: Semiconductors | I44: CRM | J44: =XEH18 -> 0.023533491 | K44: =G15 -> 0.023528523 | L44: 0.05 | M44: 0.039059217 | N44: 0.015 | O44: 0.015 | P44: -0.054999996 | Q44: 0.015 | R44: 0.015 | S44: 0.015 | T44: 0.015 | U44: 0.036148424
B45: LULU | C45: Consumer Cyclical | E45: Retail | I45: CVX | J45: =XEH19 -> 0.038584232 | K45: =G16 -> 0.038576087 | L45: 0.05 | M45: 0.031969034 | N45: 0.015 | O45: 0.065 | P45: 0.065 | Q45: 0.065 | R45: 0.065 | S45: 0.065 | T45: 0.065 | U45: 0.022467367
...

Sheet Data & Analysis
W2: =substitute(cell,char(160),"")
D3: Raw Adj. Prices, ending on Jan. 1 of following year | P3: Raw Div. Payouts, starting Jan. 1 and ending Dec. 31 | AB3: Adj.Prices + Div. Payouts, starting and ending on Jan 1. of following year | BK3: Dividend Growth (O), Monthly | BR3: Dividend Growth (O), Quarterly | BW3: Dividend Growth (O), Yearly
E4: 2016 | F4: 2017 | G4: =F4+1 -> 2018 | H4: =G4+1 -> 2019 | I4: =H4+1 -> 2020 | J4: =I4+1 -> 2021 | K4: =J4+1 -> 2022 | L4: =K4+1 -> 2023 | M4: =L4+1 -> 2024 | N4: =M4+1 -> 2025 | Q4: 2016 | R4: 2017 | S4: =R4+1 -> 2018 | T4: =S4+1 -> 2019 | U4: =T4+1 -> 2020 | V4: =U4+1 -> 2021 | W4: =V4+1 -> 2022 | X4: =W4+1 -> 2023 | Y4: =X4+1 -> 2024 | Z4: =Y4+1 -> 2025 | AC4: 2017 | AD4: =AC4+1 -> 2018 | AE4: =AD4+1 -> 2019 | AF4: =AE4+1 -> 2020 | AG4: =AF4+1 -> 2021 | AH4: =AG4+1 -> 2022 | AI4: =AH4+1 -> 2023 | AJ4: =AI4+1 -> 2024 | AK4: 2025, e | AL4: mean | AM4: mean w/o 25 | AP4: {=TRANSPOSE(AB5:AB24)} -> VOO | AQ4: DIA | AR4: TSLA | AS4: BAC | AT4: SBUX | AU4: O | AV4: VZ | AW4: AMZN | AX4: GOOGL | AY4: CRM | AZ4: CVX | BA4: AMD | BB4: LULU | BC4: LMT | BD4: UPS | BE4: XOM | BF4: COST | BG4: V | BH4: SO | BI4: DUK | BK4: Date | BL4: Div Payout | BM4: % MoM G | BN4: Pattern | BO4: Ticket | BR4: Qtr | BS4: QoQ % G | BW4: Yr | BX4: Yr Div | BY4: YoY % G | CJ4: SPG
C5: #VALUE! | D5: VOO | E5: 180.64 | F5: 228.19 | G5: 222.74 | H5: 271.03 | I5: 317.54 | J5: 391.54 | K5: 359.36 | L5: 433.96 | M5: 548.15 | N5: {=_FV(C5,"Price")} -> 680.95 | P5: VOO | Q5: 4.138 | R5: 4.368 | S5: 4.737 | T5: 5.571 | U5: 5.303 | V5: 5.437 | W5: 5.947 | X5: 6.357 | Y5: =SUM(1.739, 1.639,1.784,1.543) -> 6.705 | Z5: 5.297 | AB5: VOO | AC5: =LN((F5+R5)/E5) -> 0.25263356 | AD5: =LN((G5+S5)/F5) -> -0.0031294809 | AE5: =LN((H5+T5)/G5) -> 0.21657086 | AF5: =LN((I5+U5)/H5) -> 0.17493662 | AG5: =LN((J5+V5)/I5) -> 0.22327455 | AH5: =LN((K5+W5)/J5) -> -0.069349585 | AI5: =LN((L5+X5)/K5) -> 0.20317025 | AJ5: =LN((M5+Y5)/L5) -> 0.24575445 | AK5: =LN((N5+(Y5*(1+Z26)))/M5) -> 0.22730931 | AL5: =AVERAGE(AC5:AK5) -> 0.16346339 | AM5: =AVERAGE(AC5:AJ5) -> 0.15548265 | AO5: Data w/ Dividends | AP5: {=TRANSPOSE(AL5:AL24)} -> 0.16346339 | AQ5: 0.14575541 | AR5: 0.35547289 | AS5: 0.14859534 | AT5: 0.112434 | AU5: 0.10981572 | AV5: 0.10473519 | AW5: 0.19594581 | AX5: 0.24066489 | AY5: 0.079653887 | AZ5: 0.13578023 | BA5: 0.43907858 | BB5: 0.058495927 | BC5: 0.13116359 | BD5: 0.077103487 | BE5: 0.14799551 | BF5: 0.23014475 | BG5: 0.17076746 | BH5: 0.16149093 | BI5: 0.13966844 | BJ5: 1 | BK5: 42397 | BL5: 0.192829 | BR5: Q216 | BS5: 0.0016736579 | BW5: 2016 | BX5: 2.33139 | BY5: n/a
C6: #VALUE! | D6: DIA | E6: 166.99 | F6: 225.07 | G6: 219.87 | H6: 253.89 | I6: 275.39 | J6: 327.95 | K6: 324.62 | L6: 370.49 | M6: 440.05 | N6: {=_FV(C6,"Price")} -> 521.71 | P6: DIA | Q6: 4.461 | R6: 4.875 | S6: 5.222 | T6: 5.953 | U6: 5.728 | V6: 5.742 | W6: 6.332 | X6: 6.804 | Y6: 6.831 | Z6: 5.26 | AB6: DIA | AC6: =LN((F6+R6)/E6) -> 0.31990622 | AD6: =LN((G6+S6)/F6) -> 9.7742591e-05 | AE6: =LN((H6+T6)/G6) -> 0.16704114 | AF6: =LN((I6+U6)/H6) -> 0.10187341 | AG6: =LN((J6+V6)/I6) -> 0.19203014 | AH6: =LN((K6+W6)/J6) -> 0.009112192 | AI6: =LN((L6+X6)/K6) -> 0.15036946 | AJ6: =LN((M6+Y6)/L6) -> 0.18746589 | AK6: =LN((N6+(Y6*(1+Z27)))/M6) -> 0.18390247 | AL6: =AVERAGE(AC6:AK6) -> 0.14575541 | AM6: =AVERAGE(AC6:AJ6) -> 0.14098702 | AO6: Raw Data | AP6: {=TRANSPOSE(O26:O45)} -> 0.14744253 | AQ6: 0.12657533 | AR6: 0.35547289 | AS6: 0.12636409 | AT6: 0.091041598 | AU6: 0.055574726 | AV6: 0.04128484 | AW6: 0.19594581 | AX6: 0.2401492 | AY6: 0.078012555 | AZ6: 0.087445526 | BA6: 0.43907858 | BB6: 0.058495927 | BC6: 0.10261296 | BD6: 0.034258851 | BE6: 0.097555623 | BF6: 0.21257529 | BG6: 0.16431414 | BH6: 0.11541509 | BI6: 0.094549057 | BJ6: 2 | BK6: 42426 | BL6: 0.192829 | BM6: =LN(BL6/BL5) -> 0 | BN6: =IF(BM6=0, "No Growth", "Growth") -> No Growth | BO6: =IF(BM6=0,1,2) -> 1 | BR6: Q316 | BS6: 0.0099835468 | BW6: =BW5+1 -> 2017 | BX6: 2.461236 | BY6: =LN(BX6/BX5) -> 0.054199007 | CH6: 4 | CI6: Q415 | CJ6: 42410 | CK6: 1.6 | CL6: n/a
C7: #VALUE! | D7: TSLA | E7: 16.8 | F7: 23.62 | G7: 20.47 | H7: 43.37 | I7: 264.51 | J7: 312.24 | K7: 173.22 | L7: 187.29 | M7: 404.6 | N7: {=_FV(C7,"Price")} -> 411.84 | P7: TSLA | Q7: 0 | R7: 0 | S7: 0 | T7: 0 | U7: 0 | V7: 0 | W7: 0 | X7: 0 | Y7: 0 | Z7: 0 | AB7: TSLA | AC7: =LN((F7+R7)/E7) -> 0.34071492 | AD7: =LN((G7+S7)/F7) -> -0.14313341 | AE7: =LN((H7+T7)/G7) -> 0.75080756 | AF7: =LN((I7+U7)/H7) -> 1.8081111 | AG7: =LN((J7+V7)/I7) -> 0.16589307 | AH7: =LN((K7+W7)/J7) -> -0.58920966 | AI7: =LN((L7+X7)/K7) -> 0.078095755 | AJ7: =LN((M7+Y7)/L7) -> 0.77024071 | AK7: =LN((N7+(Y7*(1+Z28)))/M7) -> 0.017736 | AL7: =AVERAGE(AC7:AK7) -> 0.35547289 | AM7: =AVERAGE(AC7:AJ7) -> 0.39769 | AO7: Difference | AP7: =AP5-AP6 -> 0.016020862 | AQ7: =AQ5-AQ6 -> 0.019180078 | AR7: =AR5-AR6 -> 0 | AS7: =AS5-AS6 -> 0.022231257 | AT7: =AT5-AT6 -> 0.021392398 | AU7: =AU5-AU6 -> 0.054240993 | AV7: =AV5-AV6 -> 0.063450346 | AW7: =AW5-AW6 -> 0 | ... BI7: =BI5-BI6 -> 0.045119384 | BJ7: 3 | BK7: 42459 | BL7: 0.192829 | BM7: =LN(BL7/BL6) -> 0 | BN7: =IF(BM7=0, "No Growth", "Growth") -> No Growth | BO7: =IF(BM7=0,1,2) -> 1 | BR7: Q416 | BS7: 0.0049546438 | BW7: =BW6+1 -> 2018 | BX7: 2.560074 | BY7: =LN(BX7/BX6) -> 0.039372502 | CH7: 1 | CI7: Q116 | CJ7: 42503 | CK7: 1.6 | CL7: =LN(CK7/CK6) -> 0 | CM7: =IF(CL7<=0, "No Growth", "Growth") -> No Growth
C8: #VALUE! | D8: BAC | E8: 18.56 | F8: 26.65 | G8: 24.15 | H8: 28.48 | I8: 26.41 | J8: 41.89 | K8: 32.97 | L8: 32.58 | M8: 45.49 | N8: {=_FV(C8,"Price")} -> 57.875 | P8: BAC | Q8: 0.25 | R8: 0.39 | S8: 0.54 | T8: 0.66 | U8: 0.72 | V8: 0.78 | W8: 0.86 | X8: 0.92 | Y8: =SUM((0.26*2),(0.24*2)) -> 1 | Z8: 0.8 | AB8: BAC | AC8: =LN((F8+R8)/E8) -> 0.37630852 | AD8: =LN((G8+S8)/F8) -> -0.076390847 | AE8: =LN((H8+T8)/G8) -> 0.18782742 | AF8: =LN((I8+U8)/H8) -> -0.04856196 | AG8: =LN((J8+V8)/I8) -> 0.47975337 | AH8: =LN((K8+W8)/J8) -> -0.21369915 | AI8: =LN((L8+X8)/K8) -> 0.015947382 | AJ8: =LN((M8+Y8)/L8) -> 0.35553863 | AK8: =LN((N8+(Y8*(1+Z29)))/M8) -> 0.26063473 | AL8: =AVERAGE(AC8:AK8) -> 0.14859534 | AM8: =AVERAGE(AC8:AJ8) -> 0.13459042 | BJ8: 4 | BK8: 42488 | BL8: 0.192829 | BM8: =LN(BL8/BL7) -> 0 | BN8: =IF(BM8=0, "No Growth", "Growth") -> No Growth | BO8: =IF(BM8=0,1,2) -> 1 | BR8: Q117 | BS8: 0.04194205 | BW8: =BW7+1 -> 2019 | BX8: 2.635656 | BY8: =LN(BX8/BX7) -> 0.029095943 | CH8: 2 | CI8: Q216 | CJ8: 42597 | CK8: 1.65 | CL8: =LN(CK8/CK7) -> 0.030771659 | CM8: =IF(CL8<=0, "No Growth", "Growth") -> Growth
C9: #VALUE! | D9: SBUX | E9: 45.86 | F9: 48.06 | G9: 58.98 | H9: 74.8 | I9: 87.13 | J9: 89.95 | K9: 102.22 | L9: 88.96 | M9: 105.65 | N9: {=_FV(C9,"Price")} -> 104.06 | P9: SBUX | Q9: 0.85 | R9: 1.05 | S9: 1.32 | T9: 1.49 | U9: 1.68 | V9: 1.84 | W9: 2 | X9: 2.16 | Y9: 2.32 | Z9: 1.83 | AB9: SBUX | AC9: =LN((F9+R9)/E9) -> 0.068469403 | AD9: =LN((G9+S9)/F9) -> 0.22688187 | AE9: =LN((H9+T9)/G9) -> 0.25734346 | AF9: =LN((I9+U9)/H9) -> 0.17168137 | AG9: =LN((J9+V9)/I9) -> 0.052102103 | AH9: =LN((K9+W9)/J9) -> 0.14725009 | AI9: =LN((L9+X9)/K9) -> -0.11495003 | AJ9: =LN((M9+Y9)/L9) -> 0.19366658 | AK9: =LN((N9+(Y9*(1+Z30)))/M9) -> 0.0094611099 | AL9: =AVERAGE(AC9:AK9) -> 0.112434 | AM9: =AVERAGE(AC9:AJ9) -> 0.12530561 | BJ9: 5 | BK9: 42517 | BL9: 0.192829 | BM9: =LN(BL9/BL8) -> 0 | BN9: =IF(BM9=0, "No Growth", "Growth") -> No Growth | BO9: =IF(BM9=0,1,2) -> 1 | BR9: Q217 | BS9: 0.0015785477 | BW9: =BW8+1 -> 2020 | BX9: 2.717052 | BY9: =LN(BX9/BX8) -> 0.030415362 | CH9: 3 | CI9: Q316 | CJ9: 42688 | CK9: 1.65 | CL9: =LN(CK9/CK8) -> 0 | CM9: =IF(CL9<=0, "No Growth", "Growth") -> No Growth
C10: #VALUE! | D10: O | E10: 38.22 | F10: 35.63 | G10: 48.26 | H10: 57.2 | I10: 45.11 | J10: 57.07 | K10: 58.31 | L10: 49.3 | M10: 52.13 | N10: {=_FV(C10,"Price")} -> 63.025 | P10: O | Q10: 2.33139 | R10: 2.46124 | S10: 2.56007 | T10: 2.63566 | U10: 2.71705 | V10: 2.77498 | W10: 2.972 | X10: 3.062 | Y10: 3.136 | Z10: 2.68 | AB10: O | AC10: =LN((F10+R10)/E10) -> -0.0033746044 | AD10: =LN((G10+S10)/F10) -> 0.35510338 | AE10: =LN((H10+T10)/G10) -> 0.21499874 | AF10: =LN((I10+U10)/H10) -> -0.17896252 | AG10: =LN((J10+V10)/I10) -> 0.2826536 | AH10: =LN((K10+W10)/J10) -> 0.071207577 | AI10: =LN((L10+X10)/K10) -> -0.10759247 | AJ10: =LN((M10+Y10)/L10) -> 0.11423381 | AK10: =LN((N10+(Y10*(1+Z31)))/M10) -> 0.24007396 | AL10: =AVERAGE(AC10:AK10) -> 0.10981572 | AM10: =AVERAGE(AC10:AJ10) -> 0.09353344 | BJ10: 6 | BK10: 42550 | BL10: 0.193798 | BM10: =LN(BL10/BL9) -> 0.0050125937 | BN10: =IF(BM10=0, "No Growth", "Growth") -> Growth | BO10: =IF(BM10=0,1,2) -> 2 | BR10: Q317 | BS10: 0.0031496396 | BU10: Mean | BV10: =AVERAGE(BS5:BS42) -> 0.0087280229 | BW10: =BW9+1 -> 2021 | BX10: 2.774975 | BY10: =LN(BX10/BX9) -> 0.021094269 | CH10: 4 | CI10: Q416 | CJ10: 42776 | CK10: 1.75 | CL10: =LN(CK10/CK9) -> 0.0588405 | CM10: =IF(CL10<=0, "No Growth", "Growth") -> Growth
C11: #VALUE! | D11: VZ | E11: 30.4 | F11: 35.16 | G11: 37.51 | H11: 42.21 | I11: 40.58 | J11: 41.24 | K11: 33.97 | L11: 37.15 | M11: 36.85 | N11: {=_FV(C11,"Price")} -> 44.08 | P11: VZ | Q11: 2.273 | R11: 2.324 | S11: 2.373 | T11: 2.424 | U11: 2.473 | V11: 2.524 | W11: 2.573 | X11: 2.624 | Y11: 2.673 | Z11: 2.724 | AB11: VZ | AC11: =LN((F11+R11)/E11) -> 0.20947157 | AD11: =LN((G11+S11)/F11) -> 0.1260411 | AE11: =LN((H11+T11)/G11) -> 0.17388834 | AF11: =LN((I11+U11)/H11) -> 0.019774755 | AG11: =LN((J11+V11)/I11) -> 0.075536227 | AH11: =LN((K11+W11)/J11) -> -0.12091901 | AI11: =LN((L11+X11)/K11) -> 0.15773565 | AJ11: =LN((M11+Y11)/L11) -> 0.06191901 | AK11: =LN((N11+(Y11*(1+Z32)))/M11) -> 0.23916904 | AL11: =AVERAGE(AC11:AK11) -> 0.10473519 | AM11: =AVERAGE(AC11:AJ11) -> 0.087930954 | BJ11: 7 | BK11: 42579 | BL11: 0.193798 | BM11: =LN(BL11/BL10) -> 0 | BN11: =IF(BM11=0, "No Growth", "Growth") -> No Growth | BO11: =IF(BM11=0,1,2) -> 1 | BR11: Q417 | BS11: 0.0015711075 | BU11: Stdev | BV11: =_xlfn.STDEV.S(BS5:BS42) -> 0.012164492 | BW11: =BW10+1 -> 2022 | BX11: 2.972 | BY11: =LN(BX11/BX10) -> 0.068593389 | CH11: 1 | CI11: Q117 | CJ11: 42870 | CK11: 1.75 | CL11: =LN(CK11/CK10) -> 0 | CM11: =IF(CL11<=0, "No Growth", "Growth") -> No Growth
C12: #VALUE! | D12: AMZN | E12: 41.17 | F12: 72.54 | G12: 85.94 | H12: 100.44 | I12: 160.31 | J12: 149.57 | K12: 103.13 | L12: 155.2 | M12: 237.68 | N12: {=_FV(C12,"Price")} -> 240.14 | P12: AMZN | Q12: 0 | R12: 0 | S12: 0 | T12: 0 | U12: 0 | V12: 0 | W12: 0 | X12: 0 | Y12: 0 | Z12: 0 | AB12: AMZN | AC12: =LN((F12+R12)/E12) -> 0.5664283 | AD12: =LN((G12+S12)/F12) -> 0.16951124 | AE12: =LN((H12+T12)/G12) -> 0.15591116 | AF12: =LN((I12+U12)/H12) -> 0.46754891 | AG12: =LN((J12+V12)/I12) -> -0.06934493 | AH12: =LN((K12+W12)/J12) -> -0.37177418 | AI12: =LN((L12+X12)/K12) -> 0.40872428 | AJ12: =LN((M12+Y12)/L12) -> 0.42621062 | AK12: =LN((N12+(Y12*(1+Z33)))/M12) -> 0.010296855 | AL12: =AVERAGE(AC12:AK12) -> 0.19594581 | AM12: =AVERAGE(AC12:AJ12) -> 0.21915192 | BJ12: 8 | BK12: 42612 | BL12: 0.195736 | BM12: =LN(BL12/BL11) -> 0.009950433 | BN12: =IF(BM12=0, "No Growth", "Growth") -> Growth | BO12: =IF(BM12=0,1,2) -> 2 | BR12: Q118 | BS12: 0.032435586 | BW12: =BW11+1 -> 2023 | BX12: 3.062 | BY12: =LN(BX12/BX11) -> 0.02983317 | CH12: 2 | CI12: Q217 | CJ12: 42962 | CK12: 1.8 | CL12: =LN(CK12/CK11) -> 0.028170877 | CM12: =IF(CL12<=0, "No Growth", "Growth") -> Growth
C13: #VALUE! | D13: GOOGL | E13: 40.73 | F13: 58.71 | G13: 55.91 | H13: 71.15 | I13: 90.74 | J13: 134.38 | K13: 98.16 | L13: 139.14 | M13: 203.36 | N13: {=_FV(C13,"Price")} -> 353.65 | P13: GOOGL | Q13: 0 | R13: 0 | S13: 0 | T13: 0 | U13: 0 | V13: 0 | W13: 0 | X13: 0 | Y13: 0.6 | Z13: 0.62 | AB13: GOOGL | AC13: =LN((F13+R13)/E13) -> 0.36564515 | AD13: =LN((G13+S13)/F13) -> -0.048866815 | AE13: =LN((H13+T13)/G13) -> 0.24104707 | AF13: =LN((I13+U13)/H13) -> 0.24320795 | AG13: =LN((J13+V13)/I13) -> 0.39267333 | AH13: =LN((K13+W13)/J13) -> -0.31407281 | AI13: =LN((L13+X13)/K13) -> 0.34888182 | AJ13: =LN((M13+Y13)/L13) -> 0.38244328 | AK13: =LN((N13+(Y13*(1+Z34)))/M13) -> 0.55502507 | AL13: =AVERAGE(AC13:AK13) -> 0.24066489 | AM13: =AVERAGE(AC13:AJ13) -> 0.20136987 | BJ13: 9 | BK13: 42642 | BL13: 0.195736 | BM13: =LN(BL13/BL12) -> 0 | BN13: =IF(BM13=0, "No Growth", "Growth") -> No Growth | BO13: =IF(BM13=0,1,2) -> 1 | BR13: Q218 | BS13: 0.0030349322 | BW13: =BW12+1 -> 2024 | BX13: 3.136 | BY13: =LN(BX13/BX12) -> 0.023879805 | CH13: 3 | CI13: Q317 | CJ13: 43054 | CK13: 1.85 | CL13: =LN(CK13/CK12) -> 0.027398974 | CM13: =IF(CL13<=0, "No Growth", "Growth") -> Growth
C14: #VALUE! | D14: CRM | E14: 78.28 | F14: 112.72 | G14: 150.39 | H14: 180.41 | I14: 223.21 | J14: 230.21 | K14: 166.22 | L14: 278.16 | M14: 340.03 | N14: {=_FV(C14,"Price")} -> 157.97 | P14: CRM | Q14: 0 | R14: 0 | S14: 0 | T14: 0 | U14: 0 | V14: 0 | W14: 0 | X14: 0 | Y14: 1.6 | Z14: 1.248 | AB14: CRM | AC14: =LN((F14+R14)/E14) -> 0.36461473 | AD14: =LN((G14+S14)/F14) -> 0.28832505 | AE14: =LN((H14+T14)/G14) -> 0.18200012 | AF14: =LN((I14+U14)/H14) -> 0.21288099 | AG14: =LN((J14+V14)/I14) -> 0.030878903 | AH14: =LN((K14+W14)/J14) -> -0.32567972 | AI14: =LN((L14+X14)/K14) -> 0.51488428 | AJ14: =LN((M14+Y14)/L14) -> 0.20553179 | AK14: =LN((N14+(Y14*(1+Z35)))/M14) -> -0.75655115 | AL14: =AVERAGE(AC14:AK14) -> 0.079653887 | AM14: =AVERAGE(AC14:AJ14) -> 0.18417952 | BJ14: 10 | BK14: 42671 | BL14: 0.195736 | BM14: =LN(BL14/BL13) -> 0 | BN14: =IF(BM14=0, "No Growth", "Growth") -> No Growth | BO14: =IF(BM14=0,1,2) -> 1 | BR14: Q318 | BS14: 0.001514019 | BX14: Mean | BY14: =AVERAGE(BY6:BY13) -> 0.037060431 | CH14: 4 | CI14: Q417 | CJ14: 43144 | CK14: 1.95 | CL14: =LN(CK14/CK13) -> 0.052643733 | CM14: =IF(CL14<=0, "No Growth", "Growth") -> Growth
C15: #VALUE! | D15: CVX | E15: 76.67 | F15: 89.74 | G15: 85.25 | H15: 82.9 | I15: 69.66 | J15: 113 | K15: 155.13 | L15: 136.59 | M15: 144.17 | N15: {=_FV(C15,"Price")} -> 168.43 | P15: CVX | Q15: 4.29 | R15: 4.32 | S15: 4.48 | T15: 4.76 | U15: 5.16 | V15: 5.31 | W15: 5.68 | X15: 6.04 | Y15: 6.52 | Z15: 5.13 | AB15: CVX | AC15: =LN((F15+R15)/E15) -> 0.20442238 | AD15: =LN((G15+S15)/F15) -> -0.00011143924 | AE15: =LN((H15+T15)/G15) -> 0.027877579 | AF15: =LN((I15+U15)/H15) -> -0.10254983 | AG15: =LN((J15+V15)/I15) -> 0.52968203 | AH15: =LN((K15+W15)/J15) -> 0.35283573 | AI15: =LN((L15+X15)/K15) -> -0.084009611 | AJ15: =LN((M15+Y15)/L15) -> 0.098241008 | AK15: =LN((N15+(Y15*(1+Z36)))/M15) -> 0.19563423 | AL15: =AVERAGE(AC15:AK15) -> 0.13578023 | AM15: =AVERAGE(AC15:AJ15) -> 0.12829848 | BJ15: 11 | BK15: 42703 | BL15: 0.195736 | BM15: =LN(BL15/BL14) -> 0 | BN15: =IF(BM15=0, "No Growth", "Growth") -> No Growth | BO15: =IF(BM15=0,1,2) -> 1 | BR15: Q418 | BS15: 0.0030211786 | BX15: St dev | BY15: =_xlfn.STDEV.S(BY6:BY13) -> 0.016396317 | CH15: 1 | CI15: Q118 | CJ15: 43236 | CK15: 1.95 | CL15: =LN(CK15/CK14) -> 0 | CM15: =IF(CL15<=0, "No Growth", "Growth") -> No Growth
C16: #VALUE! | D16: AMD | E16: 10.37 | F16: 13.74 | G16: 24.41 | H16: 47 | I16: 85.64 | J16: 114.25 | K16: 75.15 | L16: 167.69 | M16: 115.95 | N16: {=_FV(C16,"Price")} -> 539.49 | P16: AMD | Q16: 0 | R16: 0 | S16: 0 | T16: 0 | U16: 0 | V16: 0 | W16: 0 | X16: 0 | Y16: 0 | Z16: 0 | AB16: AMD | AC16: =LN((F16+R16)/E16) -> 0.28139426 | AD16: =LN((G16+S16)/F16) -> 0.5746816 | AE16: =LN((H16+T16)/G16) -> 0.65515472 | AF16: =LN((I16+U16)/H16) -> 0.60000486 | AG16: =LN((J16+V16)/I16) -> 0.28823657 | AH16: =LN((K16+W16)/J16) -> -0.41890291 | AI16: =LN((L16+X16)/K16) -> 0.80263092 | AJ16: =LN((M16+Y16)/L16) -> -0.36895797 | AK16: =LN((N16+(Y16*(1+Z37)))/M16) -> 1.5374652 | AL16: =AVERAGE(AC16:AK16) -> 0.43907858 | AM16: =AVERAGE(AC16:AJ16) -> 0.30178026 | BJ16: 12 | BK16: 42733 | BL16: 0.196705 | BM16: =LN(BL16/BL15) -> 0.004938332 | BN16: =IF(BM16=0, "No Growth", "Growth") -> Growth | BO16: =IF(BM16=0,1,2) -> 2 | BR16: Q119 | BS16: 0.022372504 | CH16: 2 | CI16: Q218 | CJ16: 43328 | CK16: 2 | CL16: =LN(CK16/CK15) -> 0.025317808 | CM16: =IF(CL16<=0, "No Growth", "Growth") -> Growth | CS16: Total % | CT16: Total Events, increased | CU16: Total Events, decreased | CV16: Total Qtr(s) | CW16: % chance of increase | CX16: % change of decrease
C17: #VALUE! | D17: LULU | E17: 67.51 | F17: 78.21 | G17: 147.81 | H17: 239.39 | I17: 328.68 | J17: 333.76 | K17: 306.88 | L17: 453.82 | M17: 414.2 | N17: {=_FV(C17,"Price")} -> 114.29 | P17: LULU | Q17: 0 | R17: 0 | S17: 0 | T17: 0 | U17: 0 | V17: 0 | W17: 0 | X17: 0 | Y17: 0 | Z17: 0 | AB17: LULU | AC17: =LN((F17+R17)/E17) -> 0.14712178 | AD17: =LN((G17+S17)/F17) -> 0.63653015 | AE17: =LN((H17+T17)/G17) -> 0.48216636 | AF17: =LN((I17+U17)/H17) -> 0.31699061 | AG17: =LN((J17+V17)/I17) -> 0.015337539 | AH17: =LN((K17+W17)/J17) -> -0.08396538 | AI17: =LN((L17+X17)/K17) -> 0.39124385 | AJ17: =LN((M17+Y17)/L17) -> -0.091351695 | AK17: =LN((N17+(Y17*(1+Z38)))/M17) -> -1.2876099 | AL17: =AVERAGE(AC17:AK17) -> 0.058495927 | AM17: =AVERAGE(AC17:AJ17) -> 0.22675915 | BJ17: 1 | BK17: 42765 | BL17: 0.204457 | BM17: =LN(BL17/BL16) -> 0.03865254 | BN17: =IF(BM17=0, "No Growth", "Growth") -> Growth | BO17: =IF(BM17=0,1,2) -> 2 | BR17: Q219 | BS17: 0.0014738531 | CH17: 3 | CI17: Q318 | CJ17: 43419 | CK17: 2 | CL17: =LN(CK17/CK16) -> 0 | CM17: =IF(CL17<=0, "No Growth", "Growth") -> No Growth | CR17: Q4 increases | CS17: =SUMIF(CH7:CH44, "4", CL7:CL44) -> 0.16215233 | CT17: =COUNTIFS(CH7:CH44, "4", CM7:CM44, "Growth") -> 4 | CU17: =COUNTIFS(CH7:CH44, "4", CM7:CM44, "No Growth") -> 5 | CV17: =SUM(CT17:CU17) -> 9 | CW17: =CT17/$CV17 -> 0.44444444 | CX17: =CU17/$CV17 -> 0.55555556
C18: #VALUE! | D18: LMT | E18: 199.39 | F18: 288.78 | G18: 241.81 | H18: 366.58 | I18: 282.64 | J18: 352.1 | K18: 430.18 | L18: 409.56 | M18: 453.11 | N18: {=_FV(C18,"Price")} -> 502.09 | P18: LMT | Q18: 6.77 | R18: 7.46 | S18: 8.2 | T18: 9 | U18: 9.8 | V18: 10.6 | W18: 11.4 | X18: 12.15 | Y18: 12.75 | Z18: 9.9 | AB18: LMT | AC18: =LN((F18+R18)/E18) -> 0.39590723 | AD18: =LN((G18+S18)/F18) -> -0.14416424 | AE18: =LN((H18+T18)/G18) -> 0.4403192 | AF18: =LN((I18+U18)/H18) -> -0.22595726 | AG18: =LN((J18+V18)/I18) -> 0.24940204 | AH18: =LN((K18+W18)/J18) -> 0.22644398 | AI18: =LN((L18+X18)/K18) -> -0.019885852 | AJ18: =LN((M18+Y18)/L18) -> 0.12880175 | AK18: =LN((N18+(Y18*(1+Z39)))/M18) -> 0.12960543 | AL18: =AVERAGE(AC18:AK18) -> 0.13116359 | AM18: =AVERAGE(AC18:AJ18) -> 0.13135836 | BJ18: 2 | BK18: 42793 | BL18: 0.204457 | BM18: =LN(BL18/BL17) -> 0 | BN18: =IF(BM18=0, "No Growth", "Growth") -> No Growth | BO18: =IF(BM18=0,1,2) -> 1 | BR18: Q319 | BS18: 0.0029412054 | CH18: 4 | CI18: Q418 | CJ18: 43509 | CK18: 2.05 | CL18: =LN(CK18/CK17) -> 0.024692613 | CM18: =IF(CL18<=0, "No Growth", "Growth") -> Growth | CR18: Q3 increases | CS18: =SUMIF(CH7:CH44, "3", CL7:CL44) -> 0.17497758 | CT18: =COUNTIFS(CH7:CH44, "3", CM7:CM44, "Growth") -> 4 | CU18: =COUNTIFS(CH7:CH44, "3", CM7:CM44, "No Growth") -> 5 | CV18: =SUM(CT18:CU18) -> 9 | CW18: =CT18/$CV18 -> 0.44444444 | CX18: =CU18/$CV18 -> 0.55555556
C19: #VALUE! | D19: UPS | E19: 79.33 | F19: 95.41 | G19: 81.56 | H19: 82.82 | I19: 128.28 | J19: 170.96 | K19: 161.78 | L19: 128.87 | M19: 108.74 | N19: {=_FV(C19,"Price")} -> 107.98 | P19: UPS | Q19: 3.12 | R19: 3.32 | S19: 3.64 | T19: 3.84 | U19: 4.04 | V19: 4.08 | W19: 6.08 | X19: 6.48 | Y19: 6.52 | Z19: 4.92 | AB19: UPS | AC19: =LN((F19+R19)/E19) -> 0.21877248 | AD19: =LN((G19+S19)/F19) -> -0.11318196 | AE19: =LN((H19+T19)/G19) -> 0.060653471 | AF19: =LN((I19+U19)/H19) -> 0.46855365 | AG19: =LN((J19+V19)/I19) -> 0.31079914 | AH19: =LN((K19+W19)/J19) -> -0.018299312 | AI19: =LN((L19+X19)/K19) -> -0.17837337 | AJ19: =LN((M19+Y19)/L19) -> -0.1116137 | AK19: =LN((N19+(Y19*(1+Z40)))/M19) -> 0.056620972 | AL19: =AVERAGE(AC19:AK19) -> 0.077103487 | AM19: =AVERAGE(AC19:AJ19) -> 0.079663801 | BJ19: 3 | BK19: 42824 | BL19: 0.204457 | BM19: =LN(BL19/BL18) -> 0 | BN19: =IF(BM19=0, "No Growth", "Growth") -> No Growth | BO19: =IF(BM19=0,1,2) -> 1 | BR19: Q419 | BS19: 0.001467365 | CH19: 1 | CI19: Q119 | CJ19: 43601 | CK19: 2.05 | CL19: =LN(CK19/CK18) -> 0 | CM19: =IF(CL19<=0, "No Growth", "Growth") -> No Growth | CR19: Q2 increases | CS19: =SUMIF(CH7:CH44, "2", CL7:CL44) -> 0.28122966 | CT19: =COUNTIFS(CH7:CH44, "2", CM7:CM44, "Growth") -> 9 | CU19: =COUNTIFS(CH7:CH44, "2", CM7:CM44, "No Growth") -> 1 | CV19: =SUM(CT19:CU19) -> 10 | CW19: =CT19/$CV19 -> 0.9 | CX19: =CU19/$CV19 -> 0.1
C20: #VALUE! | D20: XOM | E20: 56.54 | F20: 61.07 | G20: 53.39 | H20: 47.43 | I20: 36.97 | J20: 66.48 | K20: 105.55 | L20: 96.74 | M20: 103.95 | N20: {=_FV(C20,"Price")} -> 136.04 | P20: XOM | Q20: 2.98 | R20: 3.06 | S20: 3.23 | T20: 3.43 | U20: 3.48 | V20: 3.49 | W20: 3.55 | X20: 3.68 | Y20: 3.84 | Z20: 2.97 | AB20: XOM | AC20: =LN((F20+R20)/E20) -> 0.12596392 | AD20: =LN((G20+S20)/F20) -> -0.075658468 | AE20: =LN((H20+T20)/G20) -> -0.048546703 | AF20: =LN((I20+U20)/H20) -> -0.1591883 | AG20: =LN((J20+V20)/I20) -> 0.63795981 | AH20: =LN((K20+W20)/J20) -> 0.49536374 | AI20: =LN((L20+X20)/K20) -> -0.049823384 | AJ20: =LN((M20+Y20)/L20) -> 0.10815792 | AK20: =LN((N20+(Y20*(1+Z41)))/M20) -> 0.29773109 | AL20: =AVERAGE(AC20:AK20) -> 0.14799551 | AM20: =AVERAGE(AC20:AJ20) -> 0.12927857 | BJ20: 4 | BK20: 42852 | BL20: 0.204457 | BM20: =LN(BL20/BL19) -> 0 | BN20: =IF(BM20=0, "No Growth", "Growth") -> No Growth | BO20: =IF(BM20=0,1,2) -> 1 | BR20: Q120 | BS20: 0.024621305 | CH20: 2 | CI20: Q219 | CJ20: 43692 | CK20: 2.1 | CL20: =LN(CK20/CK19) -> 0.024097552 | CM20: =IF(CL20<=0, "No Growth", "Growth") -> Growth | CR20: Q1 increases | CS20: =SUMIF(CH7:CH44, "1", CL7:CL44) -> -0.32289536 | CT20: =COUNTIFS(CH7:CH44, "1", CM7:CM44, "Growth") -> 4 | CU20: =COUNTIFS(CH7:CH44, "1", CM7:CM44, "No Growth") -> 6 | CV20: =SUM(CT20:CU20) -> 10 | CW20: =CT20/$CV20 -> 0.4 | CX20: =CU20/$CV20 -> 0.6
C21: #VALUE! | D21: COST | E21: 139.74 | F21: 174.84 | G21: 194.59 | H21: 279.72 | I21: 333.93 | J21: 482.27 | K21: 491.27 | L21: 688.23 | M21: 976.17 | N21: {=_FV(C21,"Price")} -> 946.68 | P21: COST | Q21: 1.75 | R21: 8.95 | S21: 2.21 | T21: 2.52 | U21: 12.75 | V21: 3.07 | W21: 3.49 | X21: 18.96 | Y21: 4.5 | Z21: 3.76 | AB21: COST | AC21: =LN((F21+R21)/E21) -> 0.27401025 | AD21: =LN((G21+S21)/F21) -> 0.11831671 | AE21: =LN((H21+T21)/G21) -> 0.37186299 | AF21: =LN((I21+U21)/H21) -> 0.21461306 | AG21: =LN((J21+V21)/I21) -> 0.37391829 | AH21: =LN((K21+W21)/J21) -> 0.025568673 | AI21: =LN((L21+X21)/K21) -> 0.3643055 | AJ21: =LN((M21+Y21)/L21) -> 0.35411293 | AK21: =LN((N21+(Y21*(1+Z42)))/M21) -> -0.025405629 | AL21: =AVERAGE(AC21:AK21) -> 0.23014475 | AM21: =AVERAGE(AC21:AJ21) -> 0.26208855 | BJ21: 5 | BK21: 42885 | BL21: 0.204457 | BM21: =LN(BL21/BL20) -> 0 | BN21: =IF(BM21=0, "No Growth", "Growth") -> No Growth | BO21: =IF(BM21=0,1,2) -> 1 | BR21: Q220 | BS21: 0.0014296055 | CH21: 3 | CI21: Q319 | CJ21: 43783 | CK21: 2.1 | CL21: =LN(CK21/CK20) -> 0 | CM21: =IF(CL21<=0, "No Growth", "Growth") -> No Growth
C22: #VALUE! | D22: V | E22: 77.85 | F22: 117.76 | G22: 128.84 | H22: 191.09 | I22: 186.74 | J22: 219.89 | K22: 225.51 | L22: 269.81 | M22: 340.06 | N22: {=_FV(C22,"Price")} -> 341.59 | P22: V | Q22: 0.585 | R22: 0.69 | S22: 0.88 | T22: 1.05 | U22: 1.22 | V22: 1.335 | W22: 1.575 | X22: 1.87 | Y22: 2.15 | Z22: 1.77 | AB22: V | AC22: =LN((F22+R22)/E22) -> 0.41970703 | AD22: =LN((G22+S22)/F22) -> 0.096729626 | AE22: =LN((H22+T22)/G22) -> 0.39965295 | AF22: =LN((I22+U22)/H22) -> -0.016515347 | AG22: =LN((J22+V22)/I22) -> 0.16946301 | AH22: =LN((K22+W22)/J22) -> 0.032196975 | AI22: =LN((L22+X22)/K22) -> 0.1862604 | AJ22: =LN((M22+Y22)/L22) -> 0.23770658 | AK22: =LN((N22+(Y22*(1+Z43)))/M22) -> 0.011705917 | AL22: =AVERAGE(AC22:AK22) -> 0.17076746 | AM22: =AVERAGE(AC22:AJ22) -> 0.19065015 | BJ22: 6 | BK22: 42915 | BL22: 0.205426 | BM22: =LN(BL22/BL21) -> 0.0047281873 | BN22: =IF(BM22=0, "No Growth", "Growth") -> Growth | BO22: =IF(BM22=0,1,2) -> 2 | BR22: Q320 | BS22: 0.0028530942 | CH22: 4 | CI22: Q419 | CJ22: 43874 | CK22: 2.1 | CL22: =LN(CK22/CK21) -> 0 | CM22: =IF(CL22<=0, "No Growth", "Growth") -> No Growth
C23: #VALUE! | D23: SO | E23: 34.24 | F23: 32.74 | G23: 37.17 | H23: 56.3 | I23: 49.17 | J23: 60.43 | K23: 61.18 | L23: 65.42 | M23: 81.9 | N23: {=_FV(C23,"Price")} -> 96.75 | P23: SO | Q23: 2.223 | R23: 2.3 | S23: 2.38 | T23: 2.46 | U23: 2.54 | V23: 2.62 | W23: 2.7 | X23: 2.78 | Y23: 2.86 | Z23: 2.2 | AB23: SO | AC23: =LN((F23+R23)/E23) -> 0.023095715 | AD23: =LN((G23+S23)/F23) -> 0.18896812 | AE23: =LN((H23+T23)/G23) -> 0.45795937 | AF23: =LN((I23+U23)/H23) -> -0.085043349 | AG23: =LN((J23+V23)/I23) -> 0.24864438 | AH23: =LN((K23+W23)/J23) -> 0.055520653 | AI23: =LN((L23+X23)/K23) -> 0.10862423 | AJ23: =LN((M23+Y23)/L23) -> 0.25899571 | AK23: =LN((N23+(Y23*(1+Z44)))/M23) -> 0.19665352 | AL23: =AVERAGE(AC23:AK23) -> 0.16149093 | AM23: =AVERAGE(AC23:AJ23) -> 0.1570956 | BJ23: 7 | BK23: 42944 | BL23: 0.205426 | BM23: =LN(BL23/BL22) -> 0 | BN23: =IF(BM23=0, "No Growth", "Growth") -> No Growth | BO23: =IF(BM23=0,1,2) -> 1 | BR23: Q420 | BS23: 0.0014235003 | CH23: 1 | CI23: Q120 | CJ23: 44021 | CK23: 1.3 | CL23: =LN(CK23/CK22) -> -0.47957308 | CM23: =IF(CL23<=0, "No Growth", "Growth") -> No Growth
C24: #VALUE! | D24: DUK | E24: 54.79 | F24: 57.09 | G24: 66.83 | H24: 77.56 | I24: 77.94 | J24: 90.57 | K24: 91.78 | L24: 89.63 | M24: 109.02 | N24: {=_FV(C24,"Price")} -> 128.31 | P24: DUK | Q24: 3.36 | R24: 3.49 | S24: 3.636 | T24: 3.746 | U24: 3.82 | V24: 3.9 | W24: 3.98 | X24: 4.06 | Y24: 4.14 | Z24: =1.045*3 -> 3.135 | AB24: DUK | AC24: =LN((F24+R24)/E24) -> 0.10045711 | AD24: =LN((G24+S24)/F24) -> 0.21050135 | AE24: =LN((H24+T24)/G24) -> 0.19606773 | AF24: =LN((I24+U24)/H24) -> 0.052736296 | AG24: =LN((J24+V24)/I24) -> 0.19234302 | AH24: =LN((K24+W24)/J24) -> 0.055722029 | AI24: =LN((L24+X24)/K24) -> 0.020597051 | AJ24: =LN((M24+Y24)/L24) -> 0.23311266 | AK24: =LN((N24+(Y24*(1+Z45)))/M24) -> 0.19547871 | AL24: =AVERAGE(AC24:AK24) -> 0.13966844 | AM24: =AVERAGE(AC24:AJ24) -> 0.13269216 | BJ24: 8 | BK24: 42977 | BL24: 0.205426 | BM24: =LN(BL24/BL23) -> 0 | BN24: =IF(BM24=0, "No Growth", "Growth") -> No Growth | BO24: =IF(BM24=0,1,2) -> 1 | BR24: Q121 | BS24: 0.002840936 | CH24: 2 | CI24: Q220 | CJ24: 44112 | CK24: 1.3 | CL24: =LN(CK24/CK23) -> 0 | CM24: =IF(CL24<=0, "No Growth", "Growth") -> No Growth
F25: 2017 | G25: =F25+1 -> 2018 | H25: =G25+1 -> 2019 | I25: =H25+1 -> 2020 | J25: =I25+1 -> 2021 | K25: =J25+1 -> 2022 | L25: =K25+1 -> 2023 | M25: =L25+1 -> 2024 | N25: =M25+1 -> 2025 | R25: 2017 | S25: =R25+1 -> 2018 | T25: =S25+1 -> 2019 | U25: =T25+1 -> 2020 | V25: =U25+1 -> 2021 | W25: =V25+1 -> 2022 | X25: =W25+1 -> 2023 | Y25: =X25+1 -> 2024 | Z25: 2025, e | BJ25: 9 | BK25: 43007 | BL25: 0.205426 | BM25: =LN(BL25/BL24) -> 0 | BN25: =IF(BM25=0, "No Growth", "Growth") -> No Growth | BO25: =IF(BM25=0,1,2) -> 1 | BR25: Q221 | BS25: 0.0014174471 | CH25: 3 | CI25: Q320 | CJ25: 44188 | CK25: 1.3 | CL25: =LN(CK25/CK24) -> 0 | CM25: =IF(CL25<=0, "No Growth", "Growth") -> No Growth
E26: VOO | F26: =LN(F5/E5) -> 0.23367251 | G26: =LN(G5/F5) -> -0.024173443 | H26: =LN(H5/G5) -> 0.19622434 | I26: =LN(I5/H5) -> 0.15837428 | J26: =LN(J5/I5) -> 0.20948389 | K26: =LN(K5/J5) -> -0.08576301 | L26: =LN(L5/K5) -> 0.18862769 | M26: =LN(M5/L5) -> 0.23359661 | N26: =LN(N5/M5) -> 0.21693991 | O26: =AVERAGE(F26:N26) -> 0.14744253 | Q26: VOO | R26: =LN(R5/Q5) -> 0.054092659 | S26: =LN(S5/R5) -> 0.081098785 | T26: =LN(T5/S5) -> 0.16217055 | U26: =LN(U5/T5) -> -0.049301873 | V26: =LN(V5/U5) -> 0.02495474 | W26: =LN(W5/V5) -> 0.089659453 | X26: =LN(X5/W5) -> 0.066669677 | Y26: =LN(Y5/X5) -> 0.053296949 | Z26: =LN(Y5*(1+AVERAGE(R26:Y26))/Y5) -> 0.058580291 | BJ26: 10 | BK26: 43039 | BL26: 0.205426 | BM26: =LN(BL26/BL25) -> 0 | BN26: =IF(BM26=0, "No Growth", "Growth") -> No Growth | BO26: =IF(BM26=0,1,2) -> 1 | BR26: Q321 | BS26: 0.002828881 | CH26: 4 | CI26: Q420 | CJ26: 44294 | CK26: 1.3 | CL26: =LN(CK26/CK25) -> 0 | CM26: =IF(CL26<=0, "No Growth", "Growth") -> No Growth
E27: DIA | F27: =LN(F6/E6) -> 0.29847753 | G27: =LN(G6/F6) -> -0.023375002 | H27: =LN(H6/G6) -> 0.14386464 | I27: =LN(I6/H6) -> 0.081287172 | J27: =LN(J6/I6) -> 0.17467288 | K27: =LN(K6/J6) -> -0.01020589 | L27: =LN(L6/K6) -> 0.13217119 | M27: =LN(M6/L6) -> 0.1720619 | N27: =LN(N6/M6) -> 0.17022352 | O27: =AVERAGE(F27:N27) -> 0.12657533 | Q27: DIA | R27: =LN(R6/Q6) -> 0.088747148 | S27: =LN(S6/R6) -> 0.068760366 | T27: =LN(T6/S6) -> 0.13101482 | U27: =LN(U6/T6) -> -0.038528865 | V27: =LN(V6/U6) -> 0.002441152 | W27: =LN(W6/V6) -> 0.09780856 | X27: =LN(X6/W6) -> 0.071894533 | Y27: =LN(Y6/X6) -> 0.0039604012 | Z27: =LN(Y6*(1+AVERAGE(R27:Y27))/Y6) -> 0.051892267 | BJ27: 11 | BK27: 43069 | BL27: 0.205426 | BM27: =LN(BL27/BL26) -> 0 | BN27: =IF(BM27=0, "No Growth", "Growth") -> No Growth | BO27: =IF(BM27=0,1,2) -> 1 | BR27: Q421 | BS27: 0.050639918 | CH27: 1 | CI27: Q121 | CJ27: 44378 | CK27: 1.4 | CL27: =LN(CK27/CK26) -> 0.074107972 | CM27: =IF(CL27<=0, "No Growth", "Growth") -> Growth
E28: TSLA | F28: =LN(F7/E7) -> 0.34071492 | G28: =LN(G7/F7) -> -0.14313341 | H28: =LN(H7/G7) -> 0.75080756 | I28: =LN(I7/H7) -> 1.8081111 | J28: =LN(J7/I7) -> 0.16589307 | K28: =LN(K7/J7) -> -0.58920966 | L28: =LN(L7/K7) -> 0.078095755 | M28: =LN(M7/L7) -> 0.77024071 | N28: =LN(N7/M7) -> 0.017736 | O28: =AVERAGE(F28:N28) -> 0.35547289 | Q28: TSLA | BJ28: 12 | BK28: 43098 | BL28: 0.206395 | BM28: =LN(BL28/BL27) -> 0.0047059367 | BN28: =IF(BM28=0, "No Growth", "Growth") -> Growth | BO28: =IF(BM28=0,1,2) -> 2 | BR28: Q122 | BS28: 0.026416027 | CH28: 2 | CI28: Q221 | CJ28: 44447 | CK28: 1.5 | CL28: =LN(CK28/CK27) -> 0.068992871 | CM28: =IF(CL28<=0, "No Growth", "Growth") -> Growth
E29: BAC | F29: =LN(F8/E8) -> 0.36178042 | G29: =LN(G8/F8) -> -0.098504771 | H29: =LN(H8/G8) -> 0.16491771 | I29: =LN(I8/H8) -> -0.07545936 | J29: =LN(J8/I8) -> 0.46130441 | K29: =LN(K8/J8) -> -0.23944908 | L29: =LN(L8/K8) -> -0.011899454 | M29: =LN(M8/L8) -> 0.33379392 | N29: =LN(N8/M8) -> 0.24079299 | O29: =AVERAGE(F29:N29) -> 0.12636409 | Q29: BAC | R29: =LN(R8/Q8) -> 0.44468582 | S29: =LN(S8/R8) -> 0.3254224 | T29: =LN(T8/S8) -> 0.2006707 | U29: =LN(U8/T8) -> 0.087011377 | V29: =LN(V8/U8) -> 0.080042708 | W29: =LN(W8/V8) -> 0.09763847 | X29: =LN(X8/W8) -> 0.067441281 | Y29: =LN(Y8/X8) -> 0.083381609 | Z29: =LN(Y8*(1+AVERAGE(R29:Y29))/Y8) -> 0.15980904 | BJ29: 1 | BK29: 43131 | BL29: 0.212209 | BM29: =LN(BL29/BL28) -> 0.02777983 | BN29: =IF(BM29=0, "No Growth", "Growth") -> Growth | BO29: =IF(BM29=0,1,2) -> 2 | BR29: Q222 | BS29: 0.0013486179 | CH29: 3 | CI29: Q321 | CJ29: 44539 | CK29: 1.65 | CL29: =LN(CK29/CK28) -> 0.09531018 | CM29: =IF(CL29<=0, "No Growth", "Growth") -> Growth | CR29: 8 yr Time Frame
E30: SBUX | F30: =LN(F9/E9) -> 0.046856953 | G30: =LN(G9/F9) -> 0.20474817 | H30: =LN(H9/G9) -> 0.23761948 | I30: =LN(I9/H9) -> 0.15258337 | J30: =LN(J9/I9) -> 0.031852704 | K30: =LN(K9/J9) -> 0.12787339 | L30: =LN(L9/K9) -> -0.13894052 | M30: =LN(M9/L9) -> 0.17194491 | N30: =LN(N9/M9) -> -0.015164088 | O30: =AVERAGE(F30:N30) -> 0.091041598 | Q30: SBUX | R30: =LN(R9/Q9) -> 0.21130909 | S30: =LN(S9/R9) -> 0.22884157 | T30: =LN(T9/S9) -> 0.12114438 | U30: =LN(U9/T9) -> 0.12001767 | V30: =LN(V9/U9) -> 0.090971778 | W30: =LN(W9/V9) -> 0.083381609 | X30: =LN(X9/W9) -> 0.076961041 | Y30: =LN(Y9/X9) -> 0.071458964 | Z30: =LN(Y9*(1+AVERAGE(R30:Y30))/Y9) -> 0.11823695 | BJ30: 2 | BK30: 43159 | BL30: 0.212209 | BM30: =LN(BL30/BL29) -> 0 | BN30: =IF(BM30=0, "No Growth", "Growth") -> No Growth | BO30: =IF(BM30=0,1,2) -> 1 | BR30: Q322 | BS30: 0.0026917917 | CH30: 4 | CI30: Q421 | CJ30: 44629 | CK30: 1.65 | CL30: =LN(CK30/CK29) -> 0 | CM30: =IF(CL30<=0, "No Growth", "Growth") -> No Growth
E31: O | F31: =LN(F10/E10) -> -0.070170959 | G31: =LN(G10/F10) -> 0.30341508 | H31: =LN(H10/G10) -> 0.16995084 | I31: =LN(I10/H10) -> -0.23744995 | J31: =LN(J10/I10) -> 0.23517463 | K31: =LN(K10/J10) -> 0.021495021 | L31: =LN(L10/K10) -> -0.16784952 | M31: =LN(M10/L10) -> 0.055816518 | N31: =LN(N10/M10) -> 0.18979087 | O31: =AVERAGE(F31:N31) -> 0.055574726 | Q31: O | R31: =LN(R10/Q10) -> 0.054200632 | S31: =LN(S10/R10) -> 0.039369314 | T31: =LN(T10/S10) -> 0.029099023 | U31: =LN(U10/T10) -> 0.030413108 | V31: =LN(V10/U10) -> 0.021096807 | W31: =LN(W10/V10) -> 0.068591587 | X31: =LN(X10/W10) -> 0.02983317 | Y31: =LN(Y10/X10) -> 0.023879805 | Z31: =LN(Y10*(1+AVERAGE(R31:Y31))/Y10) -> 0.036390202 | BJ31: 3 | BK31: 43188 | BL31: 0.213178 | BM31: =LN(BL31/BL30) -> 0.0045558594 | BN31: =IF(BM31=0, "No Growth", "Growth") -> Growth | BO31: =IF(BM31=0,1,2) -> 2 | BR31: Q422 | BS31: 0.0013431835 | CH31: 1 | CI31: Q122 | CJ31: 44720 | CK31: 1.7 | CL31: =LN(CK31/CK30) -> 0.029852963 | CM31: =IF(CL31<=0, "No Growth", "Growth") -> Growth | CS31: Total % | CT31: Total events | CU31: Wt
